Workbook

Sheet Summary
A1: Data can be arranged in client's own format and linked to the component worksheets.
A3: This data is mapped to following worksheets in order to create input for MIEcalculator
A5: This approach retains compatibility with the original csv file input approach while also demonstrating the interaction of python with an xls workbook.
A7: Extending this to also work with xlsx and xlsm files will be straightforward.
A8: A decision will be required as to how many different input approaches need to be supported before carrying on with further development.
A10: It is important that the component worksheets are kept clean, particularly ensuring that there is no extraneous data that might be picked up.
A11: Formulas should be OK, only the cell value is copied.
A13: Note that MIEcalculator assumes a common % scale for current. Input data must be scaled so that 100% meter current = 100% CT current.
A15: If there is no VT then all VT corrections can be set to zero, but (for now) set k factors to 2 ( setting them to zero will give a divide by zero error in MIEcalculator).
A18: In explore_w.xlsx the load profile is defined by choosing a mean and standard deviation for both the current and the phase angle.
A19: This is used to generate a random set of points consistent with the mean and standard deviations in the load sheet.
A20: This allows a single metering installation to be assessed against a range of different loads.
A21: The site temperature range is shifted to the inputData sheet for convenience

Sheet InputData
A1: Meter
B3: Test Voltage | C3: % Rated Current | D3: Amps | E3: Power Factor | F3: Phase Angle | G3: Error | H3: U | I3: k | K3: simple angle (number only, no lag or lead)
F4: Degrees | G4: % | H4: % | K4: Degrees
B5: 63.5 | C5: 2 | D5: 0.02 | E5: 1 | F5: 0 | G5: 0.058165967 | H5: 0.074814815 | I5: 2.4816159 | K5: 0
B6: 63.5 | C6: 5 | D6: 0.05 | E6: 1 | F6: 0 | G6: 0.030594033 | H6: 0.031624503 | I6: 2.0219238 | K6: 0
B7: 63.5 | C7: 5 | D7: 0.05 | E7: 0.5 Lag | F7: 60 lag | G7: 0.071859033 | H7: 0.057352031 | I7: 2.4123949 | K7: 60
B8: 63.5 | C8: 5 | D8: 0.05 | E8: 0.8 Lead | F8: 37 lead | G8: 0.0241576 | H8: 0.072457928 | I8: 2.3368391 | K8: -37
B9: 63.5 | C9: 10 | D9: 0.1 | E9: 0.5 Lag | F9: 60 lag | G9: 0.055937433 | H9: 0.035267489 | I9: 2.0608652 | K9: 60
B10: 63.5 | C10: 10 | D10: 0.1 | E10: 0.8 Lead | F10: 37 lead | G10: 0.0023796667 | H10: 0.030874419 | I10: 2.0284055 | K10: -37
B11: 63.5 | C11: 100 | D11: 1 | E11: 1 | F11: 0 | G11: 0.0169054 | H11: 0.030100646 | I11: 2.0328012 | K11: 0
B12: 63.5 | C12: 100 | D12: 1 | E12: 0.5 Lag | F12: 60 lag | G12: 0.0210655 | H12: 0.031136878 | I12: 2.0298423 | K12: 60
B13: 63.5 | C13: 100 | D13: 1 | E13: 0.8 Lead | F13: 37 lead | G13: 0.020256767 | H13: 0.030161888 | I13: 2.0324186 | K13: -37
B14: 63.5 | C14: 200 | D14: 2 | E14: 1 | F14: 0 | G14: 0.015961233 | H14: 0.030330413 | I14: 2.0310197 | K14: 0
B16: for meter page
C17: no.of rows = | D17: 10 | E17: i.e. no. of measured points
C18: no.of columns = | D18: 5 | E18: i.e. current, phase, error, expanded uncertainty, coverage factor
A20: VT
B21: Voltage % | C21: Red Phase | E21: Yellow Phase | G21: Blue Phase | I21: Expanded Uncertainty | N21: Average over phases
C22: Ratio error | D22: Phase error | E22: Ratio error | F22: Phase error | G22: Ratio error | H22: Phase error | I22: Ratio | K22: Phase | N22: error | O22: phase | P22: uphase
C23: % | D23: min | E23: % | F23: min | G23: % | H23: min | I23: % | J23: k | K23: min | L23: k | N23: % | O23: crad | P23: crad
B24: 80 | C24: -0.025 | D24: -11.42 | E24: -0.049 | F24: -12.24 | G24: -0.017 | H24: -12.62 | I24: 0.036 | J24: 2.2 | K24: 1.24 | L24: 2.3 | N24: =AVERAGE(C24,E24,G24) -> -0.030333333 | O24: =RADIANS(AVERAGE(D24,F24,H24)/60)*100 -> -0.35178081 | P24: =RADIANS(K24/60)*100 -> 0.036070138
B25: 90 | C25: -0.017 | D25: -11.38 | E25: -0.042 | F25: -12.1 | G25: -0.009 | H25: -12.54 | I25: 0.036 | J25: 2.2 | K25: 1.24 | L25: 2.3 | N25: =AVERAGE(C25,E25,G25) -> -0.022666667 | O25: =RADIANS(AVERAGE(D25,F25,H25)/60)*100 -> -0.34925978 | P25: =RADIANS(K25/60)*100 -> 0.036070138
B26: 100 | C26: -0.01 | D26: -11.3 | E26: -0.033 | F26: -12.14 | G26: -0.005 | H26: -12.52 | I26: 0.036 | J26: 2.2 | K26: 1.24 | L26: 2.3 | N26: =AVERAGE(C26,E26,G26) -> -0.016 | O26: =RADIANS(AVERAGE(D26,F26,H26)/60)*100 -> -0.348678 | P26: =RADIANS(K26/60)*100 -> 0.036070138
B27: 110 | C27: -0.006 | D27: -11.16 | E27: -0.024 | F27: -12.16 | G27: -0.004 | H27: -12.49 | I27: 0.036 | J27: 2.2 | K27: 1.24 | L27: 2.3 | N27: =AVERAGE(C27,E27,G27) -> -0.011333333 | O27: =RADIANS(AVERAGE(D27,F27,H27)/60)*100 -> -0.34722356 | P27: =RADIANS(K27/60)*100 -> 0.036070138
B28: 120 | C28: -0.005 | D28: -11.06 | E28: -0.02 | F28: -12.15 | G28: -0.003 | H28: -12.43 | I28: 0.036 | J28: 2.2 | K28: 1.24 | L28: 2.3 | N28: =AVERAGE(C28,E28,G28) -> -0.0093333333 | O28: =RADIANS(AVERAGE(D28,F28,H28)/60)*100 -> -0.34557519 | P28: =RADIANS(K28/60)*100 -> 0.036070138
B30: for VT page
C31: no.of rows = | D31: 5 | E31: i.e. no. of voltage points
C32: no.of columns = | D32: 7 | E32: i.e. voltage, ratio error, expanded uncertainty, coverage factor, phase error, expanded uncertainty, coverage factor
A34: CT
B35: Current % | C35: Red Phase | E35: Yellow Phase | G35: Blue Phase | I35: Expanded Uncertainty | N35: Average over phases
C36: Ratio error | D36: Phase error | E36: Ratio error | F36: Phase error | G36: Ratio error | H36: Phase error | I36: Ratio | K36: Phase | N36: error | O36: phase | P36: uphase
C37: % | D37: min | E37: % | F37: min | G37: % | H37: min | I37: % | J37: k | K37: min | L37: k | N37: % | O37: crad | P37: crad
B38: 5 | C38: -0.23689826 | D38: 35.0725 | E38: -0.25816585 | F38: 37.2007 | G38: -0.30879615 | H38: 36.9181 | I38: 0.039751834 | J38: 2.1631071 | K38: 1.9271588 | L38: 2.2158784 | N38: =AVERAGE(C38,E38,G38) -> -0.26795342 | O38: =RADIANS(AVERAGE(D38,F38,H38)/60)*100 -> 1.0587487 | P38: =RADIANS(K38/60)*100 -> 0.056058778
B39: 10 | C39: -0.13668309 | D39: 28.2825 | E39: -0.13839822 | F39: 28.9533 | G39: -0.18387067 | H39: 28.5855 | I39: 0.039746599 | J39: 2.1633007 | K39: 1.9268257 | L39: 2.2162775 | N39: =AVERAGE(C39,E39,G39) -> -0.15298399 | O39: =RADIANS(AVERAGE(D39,F39,H39)/60)*100 -> 0.83214681 | P39: =RADIANS(K39/60)*100 -> 0.056049086
B40: 20 | C40: -0.044924926 | D40: 25.016 | E40: -0.05500793 | F40: 23.6948 | G40: -0.092261824 | H40: 23.222 | I40: 0.039745633 | J40: 2.1633007 | K40: 1.9268257 | L40: 2.2162775 | N40: =AVERAGE(C40,E40,G40) -> -0.064064893 | O40: =RADIANS(AVERAGE(D40,F40,H40)/60)*100 -> 0.69748011 | P40: =RADIANS(K40/60)*100 -> 0.056049086
B41: 60 | C41: 0.071842865 | D41: 21.7385 | E41: 0.044265443 | F41: 15.7817 | G41: 0.0099640598 | H41: 16.1807 | I41: 0.03974588 | J41: 2.1633007 | K41: 1.9268257 | L41: 2.2162775 | N41: =AVERAGE(C41,E41,G41) -> 0.042024123 | O41: =RADIANS(AVERAGE(D41,F41,H41)/60)*100 -> 0.52069862 | P41: =RADIANS(K41/60)*100 -> 0.056049086
B42: 100 | C42: 0.093577355 | D42: 15.828 | E42: 0.07619631 | F42: 14.3994 | G42: 0.052835013 | H42: 15.0096 | I42: 0.039747233 | J42: 2.1633007 | K42: 1.9268257 | L42: 2.2162775 | N42: =AVERAGE(C42,E42,G42) -> 0.074202893 | O42: =RADIANS(AVERAGE(D42,F42,H42)/60)*100 -> 0.43863033 | P42: =RADIANS(K42/60)*100 -> 0.056049086
B43: 120 | C43: 0.095818268 | D43: 15.1753 | E43: 0.08273457 | F43: 14.6173 | G43: 0.064153748 | H43: 15.2533 | I43: 0.03974666 | J43: 2.1633007 | K43: 1.9268257 | L43: 2.2162775 | N43: =AVERAGE(C43,E43,G43) -> 0.080902195 | O43: =RADIANS(AVERAGE(D43,F43,H43)/60)*100 -> 0.43677737 | P43: =RADIANS(K43/60)*100 -> 0.056049086
B45: for CT page
C46: no.of rows = | D46: 6 | E46: i.e. no. of current points
...

Sheet project
A1: meter.csv
A2: meter_inf.csv
A3: VT.csv
A4: Vte_inf.csv
A5: VTp_inf.csv
A6: CT.csv
A7: Cte_inf.csv
A8: CTp_inf.csv
A9: site_inf.csv
A10: load.txt

Sheet meter
A1: =InputData!D17 -> 10 | B1: =InputData!D18 -> 5
A2: =InputData!C5 -> 2 | B2: =InputData!K5 -> 0 | C2: =InputData!G5 -> 0.058165967 | D2: =InputData!H5 -> 0.074814815 | E2: =InputData!I5 -> 2.4816159
A3: =InputData!C6 -> 5 | B3: =InputData!K6 -> 0 | C3: =InputData!G6 -> 0.030594033 | D3: =InputData!H6 -> 0.031624503 | E3: =InputData!I6 -> 2.0219238
A4: =InputData!C7 -> 5 | B4: =InputData!K7 -> 60 | C4: =InputData!G7 -> 0.071859033 | D4: =InputData!H7 -> 0.057352031 | E4: =InputData!I7 -> 2.4123949
A5: =InputData!C8 -> 5 | B5: =InputData!K8 -> -37 | C5: =InputData!G8 -> 0.0241576 | D5: =InputData!H8 -> 0.072457928 | E5: =InputData!I8 -> 2.3368391
A6: =InputData!C9 -> 10 | B6: =InputData!K9 -> 60 | C6: =InputData!G9 -> 0.055937433 | D6: =InputData!H9 -> 0.035267489 | E6: =InputData!I9 -> 2.0608652
A7: =InputData!C10 -> 10 | B7: =InputData!K10 -> -37 | C7: =InputData!G10 -> 0.0023796667 | D7: =InputData!H10 -> 0.030874419 | E7: =InputData!I10 -> 2.0284055
A8: =InputData!C11 -> 100 | B8: =InputData!K11 -> 0 | C8: =InputData!G11 -> 0.0169054 | D8: =InputData!H11 -> 0.030100646 | E8: =InputData!I11 -> 2.0328012
A9: =InputData!C12 -> 100 | B9: =InputData!K12 -> 60 | C9: =InputData!G12 -> 0.0210655 | D9: =InputData!H12 -> 0.031136878 | E9: =InputData!I12 -> 2.0298423
A10: =InputData!C13 -> 100 | B10: =InputData!K13 -> -37 | C10: =InputData!G13 -> 0.020256767 | D10: =InputData!H13 -> 0.030161888 | E10: =InputData!I13 -> 2.0324186
A11: =InputData!C14 -> 200 | B11: =InputData!K14 -> 0 | C11: =InputData!G14 -> 0.015961233 | D11: =InputData!H14 -> 0.030330413 | E11: =InputData!I14 -> 2.0310197

Sheet meter_inf
A1: 7 | B1: 6
A2: Meter temperature coefficient | B2: 0 | C2: %/deg | D2: =0.02/2 -> 0.01 | E2: norm | F2: 12
A3: Meter calibration temperature | B3: 23 | C3: deg | D3: 0 | E3: norm | F3: 12
A4: Meter annual drift | B4: 0 | C4: % | D4: 0 | E4: norm | F4: 12
A5: Meter voltage dependence | B5: 0 | C5: %/(%V) | D5: =0.2/(2*10) -> 0.01 | E5: norm | F5: 12
A6: Meter frequency dependence | B6: 0 | C6: %/(%f) | D6: =0.1/(2*2) -> 0.025 | E6: norm | F6: 12
A7: Meter field dependence | B7: 0 | C7: %/mT | D7: 0 | E7: norm | F7: 12
A8: Meter harmonic dependence | B8: 0 | C8: %/(%dist) | D8: =0.4/(2*10) -> 0.02 | E8: norm | F8: 12

Sheet VT
A1: Not Tettex | B1: VT5 | C1: RITZ | D1: 39190
A2: =InputData!D31 -> 5 | B2: =InputData!D32 -> 7
A3: =InputData!B24 -> 80 | B3: =InputData!N24 -> -0.030333333 | C3: =InputData!I24 -> 0.036 | D3: =InputData!J24 -> 2.2 | E3: =InputData!O24 -> -0.35178081 | F3: =InputData!P24 -> 0.036070138 | G3: =InputData!L24 -> 2.3
A4: =InputData!B25 -> 90 | B4: =InputData!N25 -> -0.022666667 | C4: =InputData!I25 -> 0.036 | D4: =InputData!J25 -> 2.2 | E4: =InputData!O25 -> -0.34925978 | F4: =InputData!P25 -> 0.036070138 | G4: =InputData!L25 -> 2.3
A5: =InputData!B26 -> 100 | B5: =InputData!N26 -> -0.016 | C5: =InputData!I26 -> 0.036 | D5: =InputData!J26 -> 2.2 | E5: =InputData!O26 -> -0.348678 | F5: =InputData!P26 -> 0.036070138 | G5: =InputData!L26 -> 2.3
A6: =InputData!B27 -> 110 | B6: =InputData!N27 -> -0.011333333 | C6: =InputData!I27 -> 0.036 | D6: =InputData!J27 -> 2.2 | E6: =InputData!O27 -> -0.34722356 | F6: =InputData!P27 -> 0.036070138 | G6: =InputData!L27 -> 2.3
A7: =InputData!B28 -> 120 | B7: =InputData!N28 -> -0.0093333333 | C7: =InputData!I28 -> 0.036 | D7: =InputData!J28 -> 2.2 | E7: =InputData!O28 -> -0.34557519 | F7: =InputData!P28 -> 0.036070138 | G7: =InputData!L28 -> 2.3

Sheet VTe_inf
A1: 4 | B1: 6
A2: VT temperature coefficient of error | B2: 0.0039 | C2: /deg | D2: =B2/10 -> 0.00039 | E2: norm | F2: 12
A3: VT calibration temperature | B3: 23 | C3: deg | D3: 0.1 | E3: norm | F3: 12
A4: VT burden coefficient of error | B4: 0 | C4: - | D4: 0 | E4: norm | F4: 12
A5: VT calibration burden | B5: =1/63.5^2 -> 0.0002480005 | C5: S | D5: =B5/10 -> 2.480005e-05 | E5: norm | F5: 12

Sheet VTp_inf
A1: 2 | B1: 6
A2: VT temperature coefficient of phase | B2: 0.0039 | C2: /deg | D2: =B2/10 -> 0.00039 | E2: norm | F2: 12
A3: VT burden coefficient of phase | B3: 0 | C3: - | D3: 0 | E3: norm | F3: 12

Sheet CT
A1: T | B1: E | C1: 1 | D1: 39722
A2: =InputData!D46 -> 6 | B2: =InputData!D47 -> 7
A3: =InputData!B38 -> 5 | B3: =InputData!N38 -> -0.26795342 | C3: =InputData!I38 -> 0.039751834 | D3: =InputData!J38 -> 2.1631071 | E3: =InputData!O38 -> 1.0587487 | F3: =InputData!P38 -> 0.056058778 | G3: =InputData!L38 -> 2.2158784
A4: =InputData!B39 -> 10 | B4: =InputData!N39 -> -0.15298399 | C4: =InputData!I39 -> 0.039746599 | D4: =InputData!J39 -> 2.1633007 | E4: =InputData!O39 -> 0.83214681 | F4: =InputData!P39 -> 0.056049086 | G4: =InputData!L39 -> 2.2162775
A5: =InputData!B40 -> 20 | B5: =InputData!N40 -> -0.064064893 | C5: =InputData!I40 -> 0.039745633 | D5: =InputData!J40 -> 2.1633007 | E5: =InputData!O40 -> 0.69748011 | F5: =InputData!P40 -> 0.056049086 | G5: =InputData!L40 -> 2.2162775
A6: =InputData!B41 -> 60 | B6: =InputData!N41 -> 0.042024123 | C6: =InputData!I41 -> 0.03974588 | D6: =InputData!J41 -> 2.1633007 | E6: =InputData!O41 -> 0.52069862 | F6: =InputData!P41 -> 0.056049086 | G6: =InputData!L41 -> 2.2162775
A7: =InputData!B42 -> 100 | B7: =InputData!N42 -> 0.074202893 | C7: =InputData!I42 -> 0.039747233 | D7: =InputData!J42 -> 2.1633007 | E7: =InputData!O42 -> 0.43863033 | F7: =InputData!P42 -> 0.056049086 | G7: =InputData!L42 -> 2.2162775
A8: =InputData!B43 -> 120 | B8: =InputData!N43 -> 0.080902195 | C8: =InputData!I43 -> 0.03974666 | D8: =InputData!J43 -> 2.1633007 | E8: =InputData!O43 -> 0.43677737 | F8: =InputData!P43 -> 0.056049086 | G8: =InputData!L43 -> 2.2162775

Sheet CTe_inf
A1: 4 | B1: 6
A2: CT temperature coefficient of error | B2: 0.0039 | C2: /deg | D2: =B2/10 -> 0.00039 | E2: norm | F2: 12
A3: CT calibration temperature | B3: 23 | C3: deg | D3: 0.1 | E3: norm | F3: 12
A4: CT burden coefficient of error | B4: 0 | C4: - | D4: 0 | E4: norm | F4: 12
A5: CT calibration burden | B5: 1 | C5: ohm | D5: =B5/10 -> 0.1 | E5: norm | F5: 10

Sheet CTp_inf
A1: 2 | B1: 6
A2: CT temperature coefficient of phase | B2: 0.0039 | C2: /deg | D2: =B2/10 -> 0.00039 | E2: norm | F2: 12
A3: CT burden coefficient of phase | B3: 0 | C3: - | D3: 0 | E3: norm | F3: 12

Sheet site_inf
A1: 8 | B1: 6
A2: Site temperature | B2: 19.5 | C2: deg | D2: =InputData!C57 -> 10 | E2: norm | F2: 12
A3: Site voltage | B3: 0 | C3: % | D3: 3 | E3: norm | F3: 12
A4: Site frequency | B4: 0 | C4: % | D4: 0.75 | E4: norm | F4: 12
A5: Site harmonics | B5: 0 | C5: % | D5: 2 | E5: norm | F5: 12
A6: Site CT burden | B6: 1 | C6: ohm | D6: 0.1 | E6: norm | F6: 12
A7: Site VT burden | B7: =1/63.5^2 -> 0.0002480005 | C7: S | D7: =B7/10 -> 2.480005e-05 | E7: norm | F7: 12
A8: Site EM field | B8: 0 | C8: mT | D8: 0 | E8: norm | F8: 10
A9: Period of certification | B9: 1 | C9: year | D9: 0 | E9: norm | F9: 50

Sheet load
A1: =(NORMSINV(RAND())*InputData!C$51)+InputData!C$50 -> 74.652634 | B1: =(NORMSINV(RAND())*InputData!C$54)+InputData!C$53 -> 9.044221 | C1: =RAND()*A1*COS(RADIANS(B1)) -> 51.284872
A2: =(NORMSINV(RAND())*InputData!C$51)+InputData!C$50 -> 75.342265 | B2: =(NORMSINV(RAND())*InputData!C$54)+InputData!C$53 -> 5.8691081 | C2: =RAND()*A2*COS(RADIANS(B2)) -> 22.62855
A3: =(NORMSINV(RAND())*InputData!C$51)+InputData!C$50 -> 64.123175 | B3: =(NORMSINV(RAND())*InputData!C$54)+InputData!C$53 -> 4.3464432 | C3: =RAND()*A3*COS(RADIANS(B3)) -> 15.688034
A4: =(NORMSINV(RAND())*InputData!C$51)+InputData!C$50 -> 71.578218 | B4: =(NORMSINV(RAND())*InputData!C$54)+InputData!C$53 -> 3.6738795 | C4: =RAND()*A4*COS(RADIANS(B4)) -> 49.13737
A5: =(NORMSINV(RAND())*InputData!C$51)+InputData!C$50 -> 85.645425 | B5: =(NORMSINV(RAND())*InputData!C$54)+InputData!C$53 -> 3.273688 | C5: =RAND()*A5*COS(RADIANS(B5)) -> 11.531665
A6: =(NORMSINV(RAND())*InputData!C$51)+InputData!C$50 -> 63.286639 | B6: =(NORMSINV(RAND())*InputData!C$54)+InputData!C$53 -> 8.7680202 | C6: =RAND()*A6*COS(RADIANS(B6)) -> 48.282781
A7: =(NORMSINV(RAND())*InputData!C$51)+InputData!C$50 -> 84.814203 | B7: =(NORMSINV(RAND())*InputData!C$54)+InputData!C$53 -> 3.1660658 | C7: =RAND()*A7*COS(RADIANS(B7)) -> 49.908422
A8: =(NORMSINV(RAND())*InputData!C$51)+InputData!C$50 -> 77.547192 | B8: =(NORMSINV(RAND())*InputData!C$54)+InputData!C$53 -> 5.8023606 | C8: =RAND()*A8*COS(RADIANS(B8)) -> 25.894926
A9: =(NORMSINV(RAND())*InputData!C$51)+InputData!C$50 -> 62.238712 | B9: =(NORMSINV(RAND())*InputData!C$54)+InputData!C$53 -> 7.8413073 | C9: =RAND()*A9*COS(RADIANS(B9)) -> 42.841721
A10: =(NORMSINV(RAND())*InputData!C$51)+InputData!C$50 -> 66.07226 | B10: =(NORMSINV(RAND())*InputData!C$54)+InputData!C$53 -> 2.9687779 | C10: =RAND()*A10*COS(RADIANS(B10)) -> 45.65101
A11: =(NORMSINV(RAND())*InputData!C$51)+InputData!C$50 -> 76.3592 | B11: =(NORMSINV(RAND())*InputData!C$54)+InputData!C$53 -> 3.6538414 | C11: =RAND()*A11*COS(RADIANS(B11)) -> 50.346135
A12: =(NORMSINV(RAND())*InputData!C$51)+InputData!C$50 -> 79.757809 | B12: =(NORMSINV(RAND())*InputData!C$54)+InputData!C$53 -> 8.0026919 | C12: =RAND()*A12*COS(RADIANS(B12)) -> 67.537173
... A800: =(NORMSINV(RAND())*InputData!C$51)+InputData!C$50 -> 91.244363 | B800: =(NORMSINV(RAND())*InputData!C$54)+InputData!C$53 -> 6.7761201 | C800: =RAND()*A800*COS(RADIANS(B800)) -> 69.311376

Sheet gen_load
A1: =(NORMSINV(RAND())*InputData!C$51)+InputData!C$50 -> 76.557728 | B1: =(NORMSINV(RAND())*InputData!C$54)+InputData!C$53 -> 5.8009941 | C1: =RAND()*A1*COS(RADIANS(B1)) -> 22.954713
A2: =(NORMSINV(RAND())*InputData!C$51)+InputData!C$50 -> 67.967894 | B2: =(NORMSINV(RAND())*InputData!C$54)+InputData!C$53 -> 5.3808627 | C2: =RAND()*A2*COS(RADIANS(B2)) -> 38.940923
A3: =(NORMSINV(RAND())*InputData!C$51)+InputData!C$50 -> 75.464425 | B3: =(NORMSINV(RAND())*InputData!C$54)+InputData!C$53 -> 0.40839356 | C3: =RAND()*A3*COS(RADIANS(B3)) -> 29.690443
A4: =(NORMSINV(RAND())*InputData!C$51)+InputData!C$50 -> 90.413655 | B4: =(NORMSINV(RAND())*InputData!C$54)+InputData!C$53 -> 0.40365549 | C4: =RAND()*A4*COS(RADIANS(B4)) -> 43.71586
A5: =(NORMSINV(RAND())*InputData!C$51)+InputData!C$50 -> 80.977898 | B5: =(NORMSINV(RAND())*InputData!C$54)+InputData!C$53 -> 4.4842865 | C5: =RAND()*A5*COS(RADIANS(B5)) -> 55.60916
A6: =(NORMSINV(RAND())*InputData!C$51)+InputData!C$50 -> 63.007086 | B6: =(NORMSINV(RAND())*InputData!C$54)+InputData!C$53 -> 4.3159212 | C6: =RAND()*A6*COS(RADIANS(B6)) -> 20.763499
A7: =(NORMSINV(RAND())*InputData!C$51)+InputData!C$50 -> 74.069134 | B7: =(NORMSINV(RAND())*InputData!C$54)+InputData!C$53 -> 4.3118484 | C7: =RAND()*A7*COS(RADIANS(B7)) -> 9.4318683
A8: =(NORMSINV(RAND())*InputData!C$51)+InputData!C$50 -> 82.656813 | B8: =(NORMSINV(RAND())*InputData!C$54)+InputData!C$53 -> 4.6064242 | C8: =RAND()*A8*COS(RADIANS(B8)) -> 62.447248
A9: =(NORMSINV(RAND())*InputData!C$51)+InputData!C$50 -> 76.258492 | B9: =(NORMSINV(RAND())*InputData!C$54)+InputData!C$53 -> 4.0132126 | C9: =RAND()*A9*COS(RADIANS(B9)) -> 67.61174
A10: =(NORMSINV(RAND())*InputData!C$51)+InputData!C$50 -> 68.830523 | B10: =(NORMSINV(RAND())*InputData!C$54)+InputData!C$53 -> 4.2413046 | C10: =RAND()*A10*COS(RADIANS(B10)) -> 31.876596
A11: =(NORMSINV(RAND())*InputData!C$51)+InputData!C$50 -> 72.332234 | B11: =(NORMSINV(RAND())*InputData!C$54)+InputData!C$53 -> 5.0321039 | C11: =RAND()*A11*COS(RADIANS(B11)) -> 65.000814
A12: =(NORMSINV(RAND())*InputData!C$51)+InputData!C$50 -> 65.426585 | B12: =(NORMSINV(RAND())*InputData!C$54)+InputData!C$53 -> 4.6669218 | C12: =RAND()*A12*COS(RADIANS(B12)) -> 19.474501
... A800: =(NORMSINV(RAND())*InputData!C$51)+InputData!C$50 -> 67.974707 | B800: =(NORMSINV(RAND())*InputData!C$54)+InputData!C$53 -> 4.9018779 | C800: =RAND()*A800*COS(RADIANS(B800)) -> 67.234189

Sheet old_load
A1: 51.133858 | B1: 31.936501 | C1: 33.772496
A2: 51.615419 | B2: 27.907676 | C2: 23.085824
A3: 51.75342 | B3: 24.139195 | C3: 18.79365
A4: 43.847701 | B4: 19.537219 | C4: 8.8136986
A5: 38.773437 | B5: 36.871935 | C5: 4.6066581
A6: 55.92043 | B6: 31.201004 | C6: 20.366832
A7: 53.641819 | B7: 23.265763 | C7: 30.853795
A8: 52.895679 | B8: 32.387389 | C8: 13.778539
A9: 55.404655 | B9: 36.193747 | C9: 13.371088
A10: 44.02688 | B10: 40.712342 | C10: 29.64315
A11: 71.634471 | B11: 38.002047 | C11: 41.423541
A12: 51.188421 | B12: 24.371076 | C12: 42.807921
... A800: 60.154416 | B800: 45.01739 | C800: 4.1171707

Sheet 80_5_15_5
A1: 80.196978 | B1: 15.019404 | C1: 43.385587
A2: 78.43895 | B2: 12.353341 | C2: 7.5173647
A3: 81.981957 | B3: 20.957801 | C3: 2.7675376
A4: 78.053435 | B4: 14.050284 | C4: 50.504264
A5: 85.125336 | B5: 9.2961826 | C5: 72.198606
A6: 87.917258 | B6: 6.0958293 | C6: 66.207487
A7: 80.314613 | B7: 15.485642 | C7: 64.087026
A8: 82.464849 | B8: 15.275035 | C8: 75.694025
A9: 74.09191 | B9: 11.695835 | C9: 46.485308
A10: 79.440911 | B10: 25.413443 | C10: 16.274512
A11: 80.377572 | B11: 16.32284 | C11: 76.729838
A12: 79.939463 | B12: 20.745004 | C12: 36.109811
... A800: 78.528469 | B800: 14.587752 | C800: 43.240744

Sheet 30_8_15_20
A1: 16.028667 | B1: 28.253506 | C1: 13.00575
A2: 26.973683 | B2: -18.676876 | C2: 22.925051
A3: 35.640027 | B3: -10.590306 | C3: 27.021329
A4: 32.251311 | B4: 40.707545 | C4: 0.26629978
A5: 25.4393 | B5: 44.334792 | C5: 2.3497291
A6: 34.034295 | B6: -23.453455 | C6: 9.0147147
A7: 36.960135 | B7: 21.85116 | C7: 15.768469
A8: 22.033817 | B8: 37.637094 | C8: 4.6122179
A9: 27.825042 | B9: 56.339064 | C9: 0.81766622
A10: 21.650679 | B10: 19.070219 | C10: 18.287222
A11: 30.666138 | B11: -13.912775 | C11: 3.6111984
A12: 35.750668 | B12: -15.1312 | C12: 24.104892
... A800: 19.591187 | B800: 39.081816 | C800: 10.362273
