Workbook

Sheet NOTES
A1: Notes
A3: Data can be arranged in client's own format and linked to the component worksheets.
A5: This data is mapped to following worksheets in order to create input for MIEcalculator
A7: This approach retains compatibility with the original csv file input approach while also demonstrating the interaction of python with an xls workbook.
A9: Extending this to also work with xlsx and xlsm files will be straightforward.
A11: A decision will be required as to how many different input approaches need to be supported before carrying on with further development.
A13: It is important that the component worksheets are kept clean, particularly ensuring that there is no extraneous data that might be picked up.
A14: Formulas should be OK, only the cell value is copied.
A16: Note that MIEcalculator assumes a common % scale for current. Input data must be scaled so that 100% meter current = 100% CT current.
A18: If there is no VT then all but one VT corrections can be set to zero, but (for now) set k factors to 2 ( setting them to zero will give a divide by zero error in MIEcalculator).
A19: (It is a feature/bug of the curve fitting program that one point should be set to, say, 0.0001 and the others to 0.0. Similarly set the uncertainty to 0.0001)
A25: Obtain the HHR data from the DA - KWh & KVArh minimum, extrapolate pf in degrees ( beware Excel works in radians ) + KVA amps the convert to 0 - 100% based on CT ratio / site capacity

Sheet InputData
A1: Meter | B1: Report Number 2135-184, #21735 / 13A117
C2: 100% =5 A | D2: Note that lagging phase angles are positive if we follow IEC convention
B3: Test Voltage | C3: % Rated Current | D3: Amps | E3: Power Factor | F3: Phase Angle | G3: Error | H3: U | I3: k
F4: Degrees | G4: % | H4: % | K4: BLUE text entered manually
B5: 230 | C5: =D5/5*100 -> 1 | D5: 0.05 | E5: =COS(RADIANS(F5)) -> 1 | F5: 0 | G5: -0.02 | H5: =0.07/E5 -> 0.07 | I5: 2.02
B6: 230 | C6: =D6/5*100 -> 2 | D6: 0.1 | E6: =COS(RADIANS(F6)) -> 0.5 | F6: 60 | G6: -0.02 | H6: =0.07/E6 -> 0.14 | I6: 2.02
B7: 230 | C7: =D7/5*100 -> 2 | D7: 0.1 | E7: =COS(RADIANS(F7)) -> 0.7998942 | F7: -36.88 | G7: -0.03 | H7: =0.07/E7 -> 0.087511574 | I7: 2.02
B8: 230 | C8: =D8/5*100 -> 5 | D8: 0.25 | E8: =COS(RADIANS(F8)) -> 1 | F8: 0 | G8: 0.01 | H8: =0.07/E8 -> 0.07 | I8: 2.02
B9: 230 | C9: =D9/5*100 -> 5 | D9: 0.25 | E9: =COS(RADIANS(F9)) -> 0.5 | F9: 60 | G9: 0.01 | H9: =0.07/E9 -> 0.14 | I9: 2.02
B10: 230 | C10: =D10/5*100 -> 5 | D10: 0.25 | E10: =COS(RADIANS(F10)) -> 0.7998942 | F10: -36.88 | G10: 0.01 | H10: =0.07/E10 -> 0.087511574 | I10: 2.02
B11: 230 | C11: =D11/5*100 -> 10 | D11: 0.5 | E11: =COS(RADIANS(F11)) -> 1 | F11: 0 | G11: 0.01 | H11: =0.07/E11 -> 0.07 | I11: 2.01
B12: 230 | C12: =D12/5*100 -> 10 | D12: 0.5 | E12: =COS(RADIANS(F12)) -> 0.5 | F12: 60 | G12: 0.02 | H12: =0.07/E12 -> 0.14 | I12: 2.01
B13: 230 | C13: =D13/5*100 -> 10 | D13: 0.5 | E13: =COS(RADIANS(F13)) -> 0.7998942 | F13: -36.88 | G13: 0 | H13: =0.07/E13 -> 0.087511574 | I13: 2.01
B14: 230 | C14: =D14/5*100 -> 50 | D14: 2.5 | E14: =COS(RADIANS(F14)) -> 1 | F14: 0 | G14: 0.02 | H14: =0.07/E14 -> 0.07 | I14: 2.01
B15: 230 | C15: =D15/5*100 -> 50 | D15: 2.5 | E15: =COS(RADIANS(F15)) -> 0.5 | F15: 60 | G15: 0.01 | H15: =0.07/E15 -> 0.14 | I15: 2.01
B16: 230 | C16: =D16/5*100 -> 50 | D16: 2.5 | E16: =COS(RADIANS(F16)) -> 0.7998942 | F16: -36.88 | G16: 0.02 | H16: =0.07/E16 -> 0.087511574 | I16: 2.01
... B25: 230 | C25: =D25/5*100 -> 400 | D25: 20 | E25: =COS(RADIANS(F25)) -> 0.7998942 | F25: -36.88 | G25: 0.01 | H25: =0.07/E25 -> 0.087511574 | I25: 2.01
B27: for meter page
C28: no.of rows = | D28: 21 | E28: i.e. no. of measured points ( entered above direct from Meter Test Cert )
C29: no.of columns = | D29: 5 | E29: i.e. current, phase, error, expanded uncertainty, coverage factor
A31: VT's | B31: LV installs = None so need to set values to near negligible….bug as setting all to zero does not work!
B32: Voltage % | C32: Red Phase | E32: Yellow Phase | G32: Blue Phase | I32: Expanded Uncertainty | N32: Average over phases
C33: Ratio error | D33: Phase error | E33: Ratio error | F33: Phase error | G33: Ratio error | H33: Phase error | I33: Ratio | K33: Phase | N33: error | O33: phase | P33: uphase
C34: % | D34: min | E34: % | F34: min | G34: % | H34: min | I34: % | J34: k | K34: min | L34: k | N34: % | O34: crad | P34: crad
B35: 80 | C35: 0 | D35: 0 | E35: 0 | F35: 0 | G35: 0 | H35: 0 | I35: 0.001 | J35: 2.2 | K35: 0.01 | L35: 2.3 | N35: =AVERAGE(C35,E35,G35) -> 0 | O35: =RADIANS(AVERAGE(D35,F35,H35)/60)*100 -> 0 | P35: =RADIANS(K35/60)*100 -> 0.00029088821
B36: 90 | C36: 0 | D36: 0 | E36: 0 | F36: 0 | G36: 0 | H36: 0 | I36: 0.001 | J36: 2.2 | K36: 0.01 | L36: 2.3 | N36: =AVERAGE(C36,E36,G36) -> 0 | O36: =RADIANS(AVERAGE(D36,F36,H36)/60)*100 -> 0 | P36: =RADIANS(K36/60)*100 -> 0.00029088821
B37: 100 | C37: 0 | D37: 0 | E37: 0 | F37: 0 | G37: 0 | H37: 0 | I37: 0.001 | J37: 2.2 | K37: 0.01 | L37: 2.3 | N37: =AVERAGE(C37,E37,G37) -> 0 | O37: =RADIANS(AVERAGE(D37,F37,H37)/60)*100 -> 0 | P37: =RADIANS(K37/60)*100 -> 0.00029088821
B38: 110 | C38: 0 | D38: 0 | E38: 0 | F38: 0 | G38: 0 | H38: 0 | I38: 0.001 | J38: 2.2 | K38: 0.01 | L38: 2.3 | N38: =AVERAGE(C38,E38,G38) -> 0 | O38: =RADIANS(AVERAGE(D38,F38,H38)/60)*100 -> 0 | P38: =RADIANS(K38/60)*100 -> 0.00029088821
B39: 120 | C39: 0 | D39: 0 | E39: 0 | F39: 0 | G39: 0 | H39: 0 | I39: 0.001 | J39: 2.2 | K39: 0.01 | L39: 2.3 | N39: =AVERAGE(C39,E39,G39) -> 0 | O39: =RADIANS(AVERAGE(D39,F39,H39)/60)*100 -> 0 | P39: =RADIANS(K39/60)*100 -> 0.00029088821
B41: for VT page
C42: no.of rows = | D42: 5 | E42: i.e. no. of voltage points
C43: no.of columns = | D43: 7 | E43: i.e. voltage, ratio error, expanded uncertainty, coverage factor, phase error, expanded uncertainty, coverage factor
B45: Report # 1510 :-
A46: CT's | B46: Full load = 5A | C46: S/2-1 | E46: S/2-2 | G46: S/2-3
B47: Current % | C47: Red Phase | E47: Yellow Phase | G47: Blue Phase | I47: Expanded Uncertainty | N47: Average over phases
C48: Ratio error | D48: Phase error | E48: Ratio error | F48: Phase error | G48: Ratio error | H48: Phase error | I48: Ratio | K48: Phase | N48: error | O48: phase | P48: uphase
C49: % | D49: min | E49: % | F49: min | G49: % | H49: min | I49: % | J49: k | K49: min | L49: k | N49: % | O49: crad | P49: crad
A50: 0 - 20 | B50: 20 | C50: 0.03 | D50: 2.58 | E50: -0.03 | F50: 3.78 | G50: -0.04 | H50: 4.88 | I50: 0.042 | J50: 2 | K50: 1.58 | L50: 2 | N50: =AVERAGE(C50,E50,G50) -> -0.013333333 | O50: =RADIANS(AVERAGE(D50,F50,H50)/60)*100 -> 0.10898612 | P50: =RADIANS(K50/60)*100 -> 0.045960337
A51: 20 - 100 | B51: 100 | C51: 0.05 | D51: 1.45 | E51: 0.03 | F51: 1.55 | G51: 0.01 | H51: 3.05 | I51: 0.04 | J51: 2 | K51: 1.36 | L51: 2 | N51: =AVERAGE(C51,E51,G51) -> 0.03 | O51: =RADIANS(AVERAGE(D51,F51,H51)/60)*100 -> 0.058662455 | P51: =RADIANS(K51/60)*100 -> 0.039560796
A52: 100 - 200 | B52: 200 | C52: 0.07 | D52: 0.62 | E52: 0.06 | F52: 0.72 | G52: 0.04 | H52: 1.52 | I52: 0.03 | J52: 2 | K52: 1 | L52: 2 | N52: =AVERAGE(C52,E52,G52) -> 0.056666667 | O52: =RADIANS(AVERAGE(D52,F52,H52)/60)*100 -> 0.027731343 | P52: =RADIANS(K52/60)*100 -> 0.029088821
...

Sheet load
A1: 0.33679754 | B1: 33.826162 | C1: 2.91
A2: 0.293495 | B2: 17.723237 | C2: 2.91
A3: 0.33102386 | B3: 14.641885 | C3: 3.33
A4: 0.23672055 | B4: 26.87814 | C4: 2.19
A5: 0.50808314 | B5: 22.043418 | C5: 4.89
A6: 0.28194765 | B6: 41.682219 | C6: 2.19
A7: 0.54849885 | B7: 19.674099 | C7: 5.37
A8: 0.31947652 | B8: 36.559635 | C8: 2.67
A9: 0.48498845 | B9: 12.380757 | C9: 4.92
A10: 0.17321016 | B10: 27.847578 | C10: 1.59
A11: 0.46862972 | B11: 9.9262455 | C11: 4.8
A12: 0.27617398 | B12: 40.341746 | C12: 2.19
... A17519: 0.70823711 | B17519: 14.886267 | C17519: 7.11

Sheet gen_load
A1: =RAND()*(InputData!C$61-InputData!C61)+InputData!C$60 -> 0.1039261 | B1: =RAND()*(InputData!C$64-InputData!C$63)+InputData!C$63 -> 15.080702 | C1: 1
A2: =RAND()*(InputData!C$61-InputData!C62+InputData!C$60) -> 0.36194026 | B2: =RAND()*(InputData!C$64-InputData!C$63)+InputData!C$63 -> 31.99524 | C2: 1
A3: =RAND()*(InputData!C$61-InputData!C63+InputData!C$60) -> 8.639211 | B3: =RAND()*(InputData!C$64-InputData!C$63)+InputData!C$63 -> 50.894145 | C3: 1
A4: =RAND()*(InputData!C$61-InputData!C64+InputData!C$60) -> -0.25502266 | B4: =RAND()*(InputData!C$64-InputData!C$63)+InputData!C$63 -> 38.699921 | C4: 1
A5: =RAND()*(InputData!C$61-InputData!C65+InputData!C$60) -> 10.946204 | B5: =RAND()*(InputData!C$64-InputData!C$63)+InputData!C$63 -> 31.695781 | C5: 1
A6: =RAND()*(InputData!C$61-InputData!C66+InputData!C$60) -> 18.424385 | B6: =RAND()*(InputData!C$64-InputData!C$63)+InputData!C$63 -> 18.53387 | C6: 1
A7: =RAND()*(InputData!C$61-InputData!C67+InputData!C$60) -> 4.8226484 | B7: =RAND()*(InputData!C$64-InputData!C$63)+InputData!C$63 -> 22.480259 | C7: 1
A8: =RAND()*(InputData!C$61-InputData!C68+InputData!C$60) -> 7.2020282 | B8: =RAND()*(InputData!C$64-InputData!C$63)+InputData!C$63 -> 54.293287 | C8: 1
A9: =RAND()*(InputData!C$61-InputData!C69+InputData!C$60) -> 1.4081763 | B9: =RAND()*(InputData!C$64-InputData!C$63)+InputData!C$63 -> 53.505447 | C9: 1
A10: =RAND()*(InputData!C$61-InputData!C70+InputData!C$60) -> 5.3351913 | B10: =RAND()*(InputData!C$64-InputData!C$63)+InputData!C$63 -> 36.826395 | C10: 1
A11: =RAND()*(InputData!C$61-InputData!C71+InputData!C$60) -> 9.201457 | B11: =RAND()*(InputData!C$64-InputData!C$63)+InputData!C$63 -> 38.883317 | C11: 1
A12: =RAND()*(InputData!C$61-InputData!C72+InputData!C$60) -> 9.4040493 | B12: =RAND()*(InputData!C$64-InputData!C$63)+InputData!C$63 -> 50.227621 | C12: 1
A13: =RAND()*(InputData!C$61-InputData!C73+InputData!C$60) -> 4.331682 | B13: =RAND()*(InputData!C$64-InputData!C$63)+InputData!C$63 -> 21.975666 | C13: 1
... A24571: =RAND()*(InputData!C$61-InputData!C24631+InputData!C$60) -> 4.6903438 | B24571: =RAND()*(InputData!C$64-InputData!C$63)+InputData!C$63 -> 10.457034 | C24571: 1
A24572: =RAND()*(InputData!C$61-InputData!C24632)+InputData!C$60 -> 11.299326 | B24572: =RAND()*(InputData!C$64-InputData!C$63)+InputData!C$63 -> 19.231957 | C24572: 1
A24573: =RAND()*(InputData!C$61-InputData!C24633)+InputData!C$60 -> 18.049921 | B24573: =RAND()*(InputData!C$64-InputData!C$63)+InputData!C$63 -> 51.415786 | C24573: 1
A24574: =RAND()*(InputData!C$61-InputData!C24634)+InputData!C$60 -> 9.635197 | B24574: =RAND()*(InputData!C$64-InputData!C$63)+InputData!C$63 -> 32.901219 | C24574: 1
A24575: =RAND()*(InputData!C$61-InputData!C24635)+InputData!C$60 -> 0.10723965 | B24575: =RAND()*(InputData!C$64-InputData!C$63)+InputData!C$63 -> 16.486544 | C24575: 1
A24576: =RAND()*(InputData!C$61-InputData!C24636)+InputData!C$60 -> 5.8094488 | B24576: =RAND()*(InputData!C$64-InputData!C$63)+InputData!C$63 -> 32.177704 | C24576: 1
A24577: =RAND()*(InputData!C$61-InputData!C24637)+InputData!C$60 -> 21.81605 | B24577: =RAND()*(InputData!C$64-InputData!C$63)+InputData!C$63 -> 16.73314 | C24577: 1
A24578: =RAND()*(InputData!C$61-InputData!C24638)+InputData!C$60 -> 1.1298312 | B24578: =RAND()*(InputData!C$64-InputData!C$63)+InputData!C$63 -> 8.3386176 | C24578: 1
A24579: =RAND()*(InputData!C$61-InputData!C24639)+InputData!C$60 -> 8.5525219 | B24579: =RAND()*(InputData!C$64-InputData!C$63)+InputData!C$63 -> 50.459103 | C24579: 1
A24580: =RAND()*(InputData!C$61-InputData!C24640)+InputData!C$60 -> 3.4200829 | B24580: =RAND()*(InputData!C$64-InputData!C$63)+InputData!C$63 -> 24.550158 | C24580: 1
A24581: =RAND()*(InputData!C$61-InputData!C24641)+InputData!C$60 -> 6.0203401 | B24581: =RAND()*(InputData!C$64-InputData!C$63)+InputData!C$63 -> 20.325723 | C24581: 1
A24582: =RAND()*(InputData!C$61-InputData!C24642)+InputData!C$60 -> 11.024297 | B24582: =RAND()*(InputData!C$64-InputData!C$63)+InputData!C$63 -> 2.4587069 | C24582: 1
A24583: =RAND()*(InputData!C$61-InputData!C24643)+InputData!C$60 -> 13.404609 | B24583: =RAND()*(InputData!C$64-InputData!C$63)+InputData!C$63 -> 9.122778 | C24583: 1
... A30000: =RAND()*(InputData!C$61-InputData!C30060)+InputData!C$60 -> 9.522874 | B30000: =RAND()*(InputData!C$64-InputData!C$63)+InputData!C$63 -> 50.241891 | C30000: 1

Sheet project
A1: meter.csv
A2: meter_inf.csv
A3: VT.csv
A4: Vte_inf.csv
A5: VTp_inf.csv
A6: CT.csv
A7: Cte_inf.csv
A8: CTp_inf.csv
A9: site_inf.csv
A10: load.txt

Sheet meter
A1: =InputData!D28 -> 21 | B1: =InputData!D29 -> 5
A2: =InputData!C5 -> 1 | B2: =InputData!F5 -> 0 | C2: =InputData!G5 -> -0.02 | D2: =InputData!H5 -> 0.07 | E2: =InputData!I5 -> 2.02
A3: =InputData!C6 -> 2 | B3: =InputData!F6 -> 60 | C3: =InputData!G6 -> -0.02 | D3: =InputData!H6 -> 0.14 | E3: =InputData!I6 -> 2.02
A4: =InputData!C7 -> 2 | B4: =InputData!F7 -> -36.88 | C4: =InputData!G7 -> -0.03 | D4: =InputData!H7 -> 0.087511574 | E4: =InputData!I7 -> 2.02
A5: =InputData!C8 -> 5 | B5: =InputData!F8 -> 0 | C5: =InputData!G8 -> 0.01 | D5: =InputData!H8 -> 0.07 | E5: =InputData!I8 -> 2.02
A6: =InputData!C9 -> 5 | B6: =InputData!F9 -> 60 | C6: =InputData!G9 -> 0.01 | D6: =InputData!H9 -> 0.14 | E6: =InputData!I9 -> 2.02
A7: =InputData!C10 -> 5 | B7: =InputData!F10 -> -36.88 | C7: =InputData!G10 -> 0.01 | D7: =InputData!H10 -> 0.087511574 | E7: =InputData!I10 -> 2.02
A8: =InputData!C11 -> 10 | B8: =InputData!F11 -> 0 | C8: =InputData!G11 -> 0.01 | D8: =InputData!H11 -> 0.07 | E8: =InputData!I11 -> 2.01
A9: =InputData!C12 -> 10 | B9: =InputData!F12 -> 60 | C9: =InputData!G12 -> 0.02 | D9: =InputData!H12 -> 0.14 | E9: =InputData!I12 -> 2.01
A10: =InputData!C13 -> 10 | B10: =InputData!F13 -> -36.88 | C10: =InputData!G13 -> 0 | D10: =InputData!H13 -> 0.087511574 | E10: =InputData!I13 -> 2.01
A11: =InputData!C14 -> 50 | B11: =InputData!F14 -> 0 | C11: =InputData!G14 -> 0.02 | D11: =InputData!H14 -> 0.07 | E11: =InputData!I14 -> 2.01
A12: =InputData!C15 -> 50 | B12: =InputData!F15 -> 60 | C12: =InputData!G15 -> 0.01 | D12: =InputData!H15 -> 0.14 | E12: =InputData!I15 -> 2.01
A13: =InputData!C16 -> 50 | B13: =InputData!F16 -> -36.88 | C13: =InputData!G16 -> 0.02 | D13: =InputData!H16 -> 0.087511574 | E13: =InputData!I16 -> 2.01
... A22: =InputData!C25 -> 400 | B22: =InputData!F25 -> -36.88 | C22: =InputData!G25 -> 0.01 | D22: =InputData!H25 -> 0.087511574 | E22: =InputData!I25 -> 2.01

Sheet meter_inf
A1: 7 | B1: 6
A2: Meter temperature coefficient | B2: 0 | C2: %/deg | D2: =0.02/2 -> 0.01 | E2: norm | F2: 12
A3: Meter calibration temperature | B3: 21 | C3: deg | D3: 0 | E3: norm | F3: 12
A4: Meter annual drift | B4: 0 | C4: % | D4: 0 | E4: norm | F4: 12
A5: Meter voltage dependence | B5: 0 | C5: %/(%V) | D5: =0.2/(2*10) -> 0.01 | E5: norm | F5: 12
A6: Meter frequency dependence | B6: 0 | C6: %/(%f) | D6: =0.1/(2*2) -> 0.025 | E6: norm | F6: 12
A7: Meter field dependence | B7: 0 | C7: %/mT | D7: 0 | E7: norm | F7: 12
A8: Meter harmonic dependence | B8: 0 | C8: %/(%dist) | D8: =0.4/(2*10) -> 0.02 | E8: norm | F8: 12

Sheet CT
A1: T | B1: E | C1: 1 | D1: 39722
A2: =InputData!D56 -> 3 | B2: =InputData!D57 -> 7
A3: =InputData!B50 -> 20 | B3: =InputData!N50 -> -0.013333333 | C3: =InputData!I50 -> 0.042 | D3: =InputData!J50 -> 2 | E3: =InputData!O50 -> 0.10898612 | F3: =InputData!P50 -> 0.045960337 | G3: =InputData!L50 -> 2
A4: =InputData!B51 -> 100 | B4: =InputData!N51 -> 0.03 | C4: =InputData!I51 -> 0.04 | D4: =InputData!J51 -> 2 | E4: =InputData!O51 -> 0.058662455 | F4: =InputData!P51 -> 0.039560796 | G4: =InputData!L51 -> 2
A5: =InputData!B52 -> 200 | B5: =InputData!N52 -> 0.056666667 | C5: =InputData!I52 -> 0.03 | D5: =InputData!J52 -> 2 | E5: =InputData!O52 -> 0.027731343 | F5: =InputData!P52 -> 0.029088821 | G5: =InputData!L52 -> 2

Sheet CTe_inf
A1: 4 | B1: 6
A2: CT temperature coefficient of error | B2: 0.0039 | C2: /deg | D2: =B2/10 -> 0.00039 | E2: norm | F2: 12
A3: CT calibration temperature | B3: 23 | C3: deg | D3: 0.1 | E3: norm | F3: 12
A4: CT burden coefficient of error | B4: 0 | C4: - | D4: 0 | E4: norm | F4: 12
A5: CT calibration burden | B5: 1 | C5: ohm | D5: =B5/10 -> 0.1 | E5: norm | F5: 10

Sheet CTp_inf
A1: 2 | B1: 6
A2: CT temperature coefficient of phase | B2: 0.0039 | C2: /deg | D2: =B2/10 -> 0.00039 | E2: norm | F2: 12
A3: CT burden coefficient of phase | B3: 0 | C3: - | D3: 0 | E3: norm | F3: 12

Sheet site_inf
A1: 8 | B1: 6
A2: Site temperature | B2: 21 | C2: deg | D2: 5 | E2: norm | F2: 12
A3: Site voltage | B3: 0 | C3: % | D3: 3 | E3: norm | F3: 12
A4: Site frequency | B4: 0 | C4: % | D4: 0.75 | E4: norm | F4: 12
A5: Site harmonics | B5: 0 | C5: % | D5: 2 | E5: norm | F5: 12
A6: Site CT burden | B6: 1 | C6: ohm | D6: 0.1 | E6: norm | F6: 12
A7: Site VT burden | B7: =1/63.5^2 -> 0.0002480005 | C7: S | D7: =B7/10 -> 2.480005e-05 | E7: norm | F7: 12
A8: Site EM field | B8: 0 | C8: mT | D8: 0 | E8: norm | F8: 10
A9: Period of certification | B9: 1 | C9: year | D9: 0 | E9: norm | F9: 50

Sheet VT
A1: Tx | B1: VT5 | C1: RITZ | D1: 39190
A2: =InputData!D42 -> 5 | B2: =InputData!D43 -> 7
A3: =InputData!B35 -> 80 | B3: =InputData!N35 -> 0 | C3: =InputData!I35 -> 0.001 | D3: =InputData!J35 -> 2.2 | E3: =InputData!O35 -> 0 | F3: =InputData!P35 -> 0.00029088821 | G3: =InputData!L35 -> 2.3
A4: =InputData!B36 -> 90 | B4: =InputData!N36 -> 0 | C4: =InputData!I36 -> 0.001 | D4: =InputData!J36 -> 2.2 | E4: =InputData!O36 -> 0 | F4: =InputData!P36 -> 0.00029088821 | G4: =InputData!L36 -> 2.3
A5: =InputData!B37 -> 100 | B5: =InputData!N37 -> 0 | C5: =InputData!I37 -> 0.001 | D5: =InputData!J37 -> 2.2 | E5: =InputData!O37 -> 0 | F5: =InputData!P37 -> 0.00029088821 | G5: =InputData!L37 -> 2.3
A6: =InputData!B38 -> 110 | B6: =InputData!N38 -> 0 | C6: =InputData!I38 -> 0.001 | D6: =InputData!J38 -> 2.2 | E6: =InputData!O38 -> 0 | F6: =InputData!P38 -> 0.00029088821 | G6: =InputData!L38 -> 2.3
A7: =InputData!B39 -> 120 | B7: =InputData!N39 -> 0 | C7: =InputData!I39 -> 0.001 | D7: =InputData!J39 -> 2.2 | E7: =InputData!O39 -> 0 | F7: =InputData!P39 -> 0.00029088821 | G7: =InputData!L39 -> 2.3

Sheet VTe_inf
A1: 4 | B1: 6
A2: VT temperature coefficient of error | B2: 0.0039 | C2: /deg | D2: =B2/10 -> 0.00039 | E2: norm | F2: 12
A3: VT calibration temperature | B3: 23 | C3: deg | D3: 0.1 | E3: norm | F3: 12
A4: VT burden coefficient of error | B4: 0 | C4: - | D4: 0 | E4: norm | F4: 12
A5: VT calibration burden | B5: =1/63.5^2 -> 0.0002480005 | C5: S | D5: =B5/10 -> 2.480005e-05 | E5: norm | F5: 12

Sheet VTp_inf
A1: 2 | B1: 6
A2: VT temperature coefficient of phase | B2: 0.0039 | C2: /deg | D2: =B2/10 -> 0.00039 | E2: norm | F2: 12
A3: VT burden coefficient of phase | B3: 0 | C3: - | D3: 0 | E3: norm | F3: 12

Sheet 1_100-30_70
A1: 0.72581903 | B1: 54.667856 | C1: 1
A2: 78.157966 | B2: -19.746657 | C2: 1
A3: 83.315907 | B3: -6.3814941 | C3: 1
A4: 25.119472 | B4: 35.088722 | C4: 1
A5: 59.946466 | B5: -22.023255 | C5: 1
A6: 95.902835 | B6: 14.091696 | C6: 1
A7: 99.560125 | B7: 42.386877 | C7: 1
A8: 50.66286 | B8: 25.347288 | C8: 1
A9: 52.206899 | B9: -3.7471842 | C9: 1
A10: 82.761371 | B10: 7.2281209 | C10: 1
A11: 87.056647 | B11: 47.64059 | C11: 1
A12: 49.63987 | B12: 47.728904 | C12: 1
... A30000: 94.747441 | B30000: -1.5308111 | C30000: 1

Sheet normal
A1: 34.265942 | B1: 47.375366 | C1: 1.8704352
A2: 39.522742 | B2: 56.308987 | C2: 5.4777523
A3: 33.339683 | B3: 40.635215 | C3: 14.071123
A4: 34.487298 | B4: 49.217267 | C4: 8.882193
A5: 66.745863 | B5: 62.587185 | C5: 8.905934
A6: 14.764709 | B6: 31.402172 | C6: 10.029283
A7: 49.56441 | B7: 52.215092 | C7: 13.856814
A8: 53.899374 | B8: 54.90068 | C8: 2.5372706
A9: 70.025724 | B9: 53.081387 | C9: 38.115896
A10: 34.312016 | B10: 28.748025 | C10: 13.952362
A11: 54.895483 | B11: 14.809542 | C11: 10.211771
A12: 55.986308 | B12: 53.899666 | C12: 24.639351
... A800: 47.409754 | B800: 26.539007 | C800: 31.135065

Sheet Sheet1
